<?xml version="1.0" ?>
<!-- =================================================================================== -->
<!-- |    This document was autogenerated by xacro from /home/iaslab/tesisti_ws/src/environment_setup/environment_description/urdf/ur5_ft_gripper.urdf.xacro | -->
<!-- |    EDITING THIS FILE BY HAND IS NOT RECOMMENDED                                 | -->
<!-- =================================================================================== -->
<robot name="workcell">
    <!--
    Base UR robot series xacro macro.

    NOTE: this is NOT a URDF. It cannot directly be loaded by consumers
    expecting a flattened '.urdf' file. See the top-level '.xacro' for that
    (but note: that .xacro must still be processed by the xacro command).

    For use in '.launch' files: use one of the 'load_urX.launch' convenience
    launch files.

    This file models the base kinematic chain of a UR robot, which then gets
    parameterised by various configuration files to convert it into a UR3(e),
    UR5(e), UR10(e) or UR16e.

    NOTE: the default kinematic parameters (ie: link lengths, frame locations,
    offets, etc) do not correspond to any particular robot. They are defaults
    only. There WILL be non-zero offsets between the Forward Kinematics results
    in TF (ie: robot_state_publisher) and the values reported by the Teach
    Pendant.

    For accurate (and robot-specific) transforms, the 'kinematics_parameters_file'
    parameter MUST point to a .yaml file containing the appropriate values for
    the targetted robot.

    If using the UniversalRobots/Universal_Robots_ROS_Driver, follow the steps
    described in the readme of that repository to extract the kinematic
    calibration from the controller and generate the required .yaml file.

    Main author of the migration to yaml configs: Ludovic Delval.

    Contributors to previous versions (in no particular order):

     - Felix Messmer
     - Kelsey Hawkins
     - Wim Meeussen
     - Shaun Edwards
     - Nadia Hammoudeh Garcia
     - Dave Hershberger
     - G. vd. Hoorn
     - Philip Long
     - Dave Coleman
     - Miguel Prada
     - Mathias Luedtke
     - Marcel Schnirring
     - Felix von Drigalski
     - Felix Exner
     - Jimmy Da Silva
     - Ajit Krisshna N L
     - Muhammad Asif Rana
  -->
    <!--
    NOTE: the macro defined in this file is NOT part of the public API of this
          package. Users CANNOT rely on this file being available, or stored in
          this location. Nor can they rely on the existence of the macro.
  -->
    <transmission name="shoulder_pan_trans">
        <type>transmission_interface/SimpleTransmission</type>
        <joint name="shoulder_pan_joint">
            <hardwareInterface>hardware_interface/PositionJointInterface</hardwareInterface>
        </joint>
        <actuator name="shoulder_pan_motor">
            <mechanicalReduction>1</mechanicalReduction>
            <hardwareInterface>hardware_interface/EffortJointInterface</hardwareInterface>
        </actuator>
    </transmission>
    <transmission name="shoulder_lift_trans">
        <type>transmission_interface/SimpleTransmission</type>
        <joint name="shoulder_lift_joint">
            <hardwareInterface>hardware_interface/PositionJointInterface</hardwareInterface>
        </joint>
        <actuator name="shoulder_lift_motor">
            <mechanicalReduction>1</mechanicalReduction>
            <hardwareInterface>hardware_interface/EffortJointInterface</hardwareInterface>
        </actuator>
    </transmission>
    <transmission name="elbow_trans">
        <type>transmission_interface/SimpleTransmission</type>
        <joint name="elbow_joint">
            <hardwareInterface>hardware_interface/PositionJointInterface</hardwareInterface>
        </joint>
        <actuator name="elbow_motor">
            <mechanicalReduction>1</mechanicalReduction>
            <hardwareInterface>hardware_interface/EffortJointInterface</hardwareInterface>
        </actuator>
    </transmission>
    <transmission name="wrist_1_trans">
        <type>transmission_interface/SimpleTransmission</type>
        <joint name="wrist_1_joint">
            <hardwareInterface>hardware_interface/PositionJointInterface</hardwareInterface>
        </joint>
        <actuator name="wrist_1_motor">
            <mechanicalReduction>1</mechanicalReduction>
            <hardwareInterface>hardware_interface/EffortJointInterface</hardwareInterface>
        </actuator>
    </transmission>
    <transmission name="wrist_2_trans">
        <type>transmission_interface/SimpleTransmission</type>
        <joint name="wrist_2_joint">
            <hardwareInterface>hardware_interface/PositionJointInterface</hardwareInterface>
        </joint>
        <actuator name="wrist_2_motor">
            <mechanicalReduction>1</mechanicalReduction>
            <hardwareInterface>hardware_interface/EffortJointInterface</hardwareInterface>
        </actuator>
    </transmission>
    <transmission name="wrist_3_trans">
        <type>transmission_interface/SimpleTransmission</type>
        <joint name="wrist_3_joint">
            <hardwareInterface>hardware_interface/PositionJointInterface</hardwareInterface>
        </joint>
        <actuator name="wrist_3_motor">
            <mechanicalReduction>1</mechanicalReduction>
            <hardwareInterface>hardware_interface/EffortJointInterface</hardwareInterface>
        </actuator>
    </transmission>
    <!-- links: main serial chain -->
    <link name="base_link" />
    <link name="base_link_inertia">
        <visual>
            <origin rpy="0 0 3.141592653589793" xyz="0 0 0" />
            <geometry>
                <mesh filename="package://ur_description/meshes/ur5/visual/base.dae" />
            </geometry>
            <material name="LightGrey">
                <color rgba="0.7 0.7 0.7 1.0" />
            </material>
        </visual>
        <collision>
            <origin rpy="0 0 3.141592653589793" xyz="0 0 0" />
            <geometry>
                <mesh filename="package://ur_description/meshes/ur5/collision/base.stl" />
            </geometry>
        </collision>
        <inertial>
            <mass value="4.0" />
            <origin rpy="0 0 0" xyz="0 0 0" />
            <inertia ixx="0.00443333156" ixy="0.0" ixz="0.0" iyy="0.00443333156" iyz="0.0" izz="0.0072" />
        </inertial>
    </link>
    <link name="shoulder_link">
        <visual>
            <origin rpy="0 0 3.141592653589793" xyz="0 0 0" />
            <geometry>
                <mesh filename="package://ur_description/meshes/ur5/visual/shoulder.dae" />
            </geometry>
            <material name="LightGrey">
                <color rgba="0.7 0.7 0.7 1.0" />
            </material>
        </visual>
        <collision>
            <origin rpy="0 0 3.141592653589793" xyz="0 0 0" />
            <geometry>
                <mesh filename="package://ur_description/meshes/ur5/collision/shoulder.stl" />
            </geometry>
        </collision>
        <inertial>
            <mass value="3.7" />
            <origin rpy="0 0 0" xyz="0 0 0" />
            <inertia ixx="0.014972352344389999" ixy="0.0" ixz="0.0" iyy="0.014972352344389999" iyz="0.0" izz="0.01040625" />
        </inertial>
    </link>
    <link name="upper_arm_link">
        <visual>
            <origin rpy="1.5707963267948966 0 -1.5707963267948966" xyz="0 0 0.13585" />
            <geometry>
                <mesh filename="package://ur_description/meshes/ur5/visual/upperarm.dae" />
            </geometry>
            <material name="LightGrey">
                <color rgba="0.7 0.7 0.7 1.0" />
            </material>
        </visual>
        <collision>
            <origin rpy="1.5707963267948966 0 -1.5707963267948966" xyz="0 0 0.13585" />
            <geometry>
                <mesh filename="package://ur_description/meshes/ur5/collision/upperarm.stl" />
            </geometry>
        </collision>
        <inertial>
            <mass value="8.393" />
            <origin rpy="0 1.5707963267948966 0" xyz="-0.2125 0.0 0.136" />
            <inertia ixx="0.1338857818623325" ixy="0.0" ixz="0.0" iyy="0.1338857818623325" iyz="0.0" izz="0.0151074" />
        </inertial>
    </link>
    <link name="forearm_link">
        <visual>
            <origin rpy="1.5707963267948966 0 -1.5707963267948966" xyz="0 0 0.0165" />
            <geometry>
                <mesh filename="package://ur_description/meshes/ur5/visual/forearm.dae" />
            </geometry>
            <material name="LightGrey">
                <color rgba="0.7 0.7 0.7 1.0" />
            </material>
        </visual>
        <collision>
            <origin rpy="1.5707963267948966 0 -1.5707963267948966" xyz="0 0 0.0165" />
            <geometry>
                <mesh filename="package://ur_description/meshes/ur5/collision/forearm.stl" />
            </geometry>
        </collision>
        <inertial>
            <mass value="2.275" />
            <origin rpy="0 1.5707963267948966 0" xyz="-0.196125 0.0 0.0165" />
            <inertia ixx="0.03121679102890359" ixy="0.0" ixz="0.0" iyy="0.03121679102890359" iyz="0.0" izz="0.004095" />
        </inertial>
    </link>
    <link name="wrist_1_link">
        <visual>
            <!-- TODO: Move this to a parameter -->
            <origin rpy="1.5707963267948966 0 0" xyz="0 0 -0.093" />
            <geometry>
                <mesh filename="package://ur_description/meshes/ur5/visual/wrist1.dae" />
            </geometry>
            <material name="LightGrey">
                <color rgba="0.7 0.7 0.7 1.0" />
            </material>
        </visual>
        <collision>
            <origin rpy="1.5707963267948966 0 0" xyz="0 0 -0.093" />
            <geometry>
                <mesh filename="package://ur_description/meshes/ur5/collision/wrist1.stl" />
            </geometry>
        </collision>
        <inertial>
            <mass value="1.219" />
            <origin rpy="0 0 0" xyz="0 0 0" />
            <inertia ixx="0.0020138887777775" ixy="0.0" ixz="0.0" iyy="0.0020138887777775" iyz="0.0" izz="0.0021942" />
        </inertial>
    </link>
    <link name="wrist_2_link">
        <visual>
            <origin rpy="0 0 0" xyz="0 0 -0.095" />
            <geometry>
                <mesh filename="package://ur_description/meshes/ur5/visual/wrist2.dae" />
            </geometry>
            <material name="LightGrey">
                <color rgba="0.7 0.7 0.7 1.0" />
            </material>
        </visual>
        <collision>
            <origin rpy="0 0 0" xyz="0 0 -0.095" />
            <geometry>
                <mesh filename="package://ur_description/meshes/ur5/collision/wrist2.stl" />
            </geometry>
        </collision>
        <inertial>
            <mass value="1.219" />
            <origin rpy="0 0 0" xyz="0 0 0" />
            <inertia ixx="0.0018310388509175" ixy="0.0" ixz="0.0" iyy="0.0018310388509175" iyz="0.0" izz="0.0021942" />
        </inertial>
    </link>
    <link name="wrist_3_link">
        <visual>
            <origin rpy="1.5707963267948966 0 0" xyz="0 0 -0.0818" />
            <geometry>
                <mesh filename="package://ur_description/meshes/ur5/visual/wrist3.dae" />
            </geometry>
            <material name="LightGrey">
                <color rgba="0.7 0.7 0.7 1.0" />
            </material>
        </visual>
        <collision>
            <origin rpy="1.5707963267948966 0 0" xyz="0 0 -0.0818" />
            <geometry>
                <mesh filename="package://ur_description/meshes/ur5/collision/wrist3.stl" />
            </geometry>
        </collision>
        <inertial>
            <mass value="0.1879" />
            <origin rpy="0 0 0" xyz="0.0 0.0 -0.01525" />
            <inertia ixx="8.062472608343e-05" ixy="0.0" ixz="0.0" iyy="8.062472608343e-05" iyz="0.0" izz="0.0001321171875" />
        </inertial>
    </link>
    <!-- joints: main serial chain -->
    <joint name="base_link-base_link_inertia" type="fixed">
        <parent link="base_link" />
        <child link="base_link_inertia" />
        <!-- 'base_link' is REP-103 aligned (so X+ forward), while the internal
           frames of the robot/controller have X+ pointing backwards.
           Use the joint between 'base_link' and 'base_link_inertia' (a dummy
           link/frame) to introduce the necessary rotation over Z (of pi rad).
      -->
        <origin rpy="0 0 3.141592653589793" xyz="0 0 0" />
    </joint>
    <joint name="shoulder_pan_joint" type="revolute">
        <parent link="base_link_inertia" />
        <child link="shoulder_link" />
        <origin rpy="0 0 0" xyz="0 0 0.089159" />
        <axis xyz="0 0 1" />
        <limit effort="150.0" lower="-6.283185307179586" upper="6.283185307179586" velocity="3.141592653589793" />
        <dynamics damping="0" friction="0" />
    </joint>
    <joint name="shoulder_lift_joint" type="revolute">
        <parent link="shoulder_link" />
        <child link="upper_arm_link" />
        <origin rpy="1.570796327 0 0" xyz="0 0 0" />
        <axis xyz="0 0 1" />
        <limit effort="150.0" lower="-6.283185307179586" upper="6.283185307179586" velocity="3.141592653589793" />
        <dynamics damping="0" friction="0" />
    </joint>
    <joint name="elbow_joint" type="revolute">
        <parent link="upper_arm_link" />
        <child link="forearm_link" />
        <origin rpy="0 0 0" xyz="-0.425 0 0" />
        <axis xyz="0 0 1" />
        <limit effort="150.0" lower="-3.141592653589793" upper="3.141592653589793" velocity="3.141592653589793" />
        <dynamics damping="0" friction="0" />
    </joint>
    <joint name="wrist_1_joint" type="revolute">
        <parent link="forearm_link" />
        <child link="wrist_1_link" />
        <origin rpy="0 0 0" xyz="-0.39225 0 0.10915" />
        <axis xyz="0 0 1" />
        <limit effort="28.0" lower="-6.283185307179586" upper="6.283185307179586" velocity="3.141592653589793" />
        <dynamics damping="0" friction="0" />
    </joint>
    <joint name="wrist_2_joint" type="revolute">
        <parent link="wrist_1_link" />
        <child link="wrist_2_link" />
        <origin rpy="1.570796327 0 0" xyz="0 -0.09465 -1.941303950897609e-11" />
        <axis xyz="0 0 1" />
        <limit effort="28.0" lower="-6.283185307179586" upper="6.283185307179586" velocity="3.141592653589793" />
        <dynamics damping="0" friction="0" />
    </joint>
    <joint name="wrist_3_joint" type="revolute">
        <parent link="wrist_2_link" />
        <child link="wrist_3_link" />
        <origin rpy="1.570796326589793 3.141592653589793 3.141592653589793" xyz="0 0.0823 -1.688001216681175e-11" />
        <axis xyz="0 0 1" />
        <limit effort="28.0" lower="-6.283185307179586" upper="6.283185307179586" velocity="3.141592653589793" />
        <dynamics damping="0" friction="0" />
    </joint>
    <!-- ROS-Industrial 'base' frame: base_link to UR 'Base' Coordinates transform -->
    <link name="base" />
    <joint name="base_link-base_fixed_joint" type="fixed">
        <!-- Note the rotation over Z of pi radians: as base_link is REP-103
           aligned (ie: has X+ forward, Y+ left and Z+ up), this is needed
           to correctly align 'base' with the 'Base' coordinate system of
           the UR controller.
      -->
        <origin rpy="0 0 3.141592653589793" xyz="0 0 0" />
        <parent link="base_link" />
        <child link="base" />
    </joint>
    <!-- ROS-Industrial 'flange' frame: attachment point for EEF models -->
    <link name="flange" />
    <joint name="wrist_3-flange" type="fixed">
        <parent link="wrist_3_link" />
        <child link="flange" />
        <origin rpy="0 -1.5707963267948966 -1.5707963267948966" xyz="0 0 0" />
    </joint>
    <!-- ROS-Industrial 'tool0' frame: all-zeros tool frame -->
    <link name="tool0" />
    <joint name="flange-tool0" type="fixed">
        <!-- default toolframe: X+ left, Y+ up, Z+ front -->
        <origin rpy="1.5707963267948966 0 1.5707963267948966" xyz="0 0 0" />
        <parent link="flange" />
        <child link="tool0" />
    </joint>
    <!-- mount the fts to the robot -->
    <joint name="ft300_fix" type="fixed">
        <origin rpy="0 0 0" xyz="0 0 0" />
        <parent link="tool0" />
        <child link="ft300_mounting_plate" />
    </joint>
    <!-- Link representing the FT300 force-torque sensor -->
    <link name="ft300_sensor">
        <inertial>
            <origin rpy="0 0 0" xyz="0 0 -0.017" />
            <mass value="0.300" />
            <inertia ixx="0.000262" ixy="0" ixz="1e-06" iyx="0" iyy="0.000265" iyz="1e-06" izx="-1e-06" izy="1e-06" izz="0.000219" />
        </inertial>
        <visual>
            <origin rpy="0 0 0" xyz="0 0 0" />
            <geometry>
                <mesh filename="package://robotiq_ft_sensor/meshes/visual/robotiq_ft300.STL" />
            </geometry>
            <material name="Robotiq-Black">
                <color rgba="0.2 0.2 0.2 1.0" />
            </material>
        </visual>
        <collision>
            <origin rpy="0 0 0" xyz="0 0 0" />
            <geometry>
                <mesh filename="package://robotiq_ft_sensor/meshes/collision/robotiq_ft300.STL" />
            </geometry>
        </collision>
    </link>
    <!-- Link representing the FT300 mounting plate -->
    <link name="ft300_mounting_plate">
        <visual>
            <origin rpy="0 0 0" xyz="0 0 0" />
            <geometry>
                <mesh filename="package://robotiq_ft_sensor/meshes/visual/mountings/robotiq_ft300-G-062-COUPLING_G-50-4M6-1D6_20181119.STL" />
            </geometry>
            <material name="Robotiq-Grey">
                <color rgba="0.4 0.4 0.4 1.0" />
            </material>
        </visual>
        <collision>
            <origin rpy="0 0 0" xyz="0 0 0" />
            <geometry>
                <mesh filename="package://robotiq_ft_sensor/meshes/collision/mountings/robotiq_ft300-G-062-COUPLING_G-50-4M6-1D6_20181119.STL" />
            </geometry>
        </collision>
        <inertial>
            <mass value="0.1" />
            <origin xyz="0 0 0" rpy="0 0 0" />
            <inertia ixx="0.03" iyy="0.03" izz="0.03" ixy="0.0" ixz="0.0" iyz="0.0" />
        </inertial>
    </link>
    <!-- Connect force sensor with mounting/coupling plate -->
    <joint name="ft300_mounting_plate" type="fixed">
        <origin rpy="0 3.141592653589793 0" xyz="0 0 0.0415" />
        <parent link="ft300_mounting_plate" />
        <child link="ft300_sensor" />
    </joint>
    <!-- FORCE REFERENCE FRAME _______________________________________________________________________________
            As specified in the documentation:
            - The Z axis passes through the center of the depression with positive direction in the tool direction.
            - The X axis traces a symmetric line centered on the connector; the positive direction
                points the opposite way away from the connector.
            - The Y axis uses the right hand thumb rule according to X-Z. -->
    <joint name="measurment_joint" type="fixed">
        <origin rpy="0 3.141592653589793 -1.5707963267948966" xyz="0 0 0" />
        <parent link="ft300_sensor" />
        <child link="robotiq_ft_frame_id" />
    </joint>
    <link name="robotiq_ft_frame_id" />
    <!-- Define materials -->
    <material name="white">
        <color rgba="1 1 1 1" />
    </material>
    <!-- Define mount link -->
    <link name="mount">
        <visual>
            <origin rpy="0 0 0" xyz="0 0 0.45" />
            <geometry>
                <box size="0.6 0.4 0.9" />
            </geometry>
            <material name="white" />
        </visual>
        <collision>
            <origin rpy="0 0 0" xyz="0 0 0.45" />
            <geometry>
                <box size="0.6 0.4 0.9" />
            </geometry>
        </collision>
        <inertial>
            <mass value="0.1" />
            <origin xyz="0 0 0" rpy="0 0 0" />
            <inertia ixx="0.03" iyy="0.03" izz="0.03" ixy="0.0" ixz="0.0" iyz="0.0" />
        </inertial>
    </link>
    <link name="table">
        <visual>
            <origin rpy="0 0 0" xyz="0 0 0.45" />
            <geometry>
                <box size="1 0.785 0.9" />
            </geometry>
            <material name="white" />
        </visual>
        <collision>
            <origin rpy="0 0 0" xyz="0 0 0.45" />
            <geometry>
                <box size="1 0.785 0.9" />
            </geometry>
        </collision>
        <inertial>
            <mass value="0.1" />
            <origin xyz="0 0 0" rpy="0 0 0" />
            <inertia ixx="0.03" iyy="0.03" izz="0.03" ixy="0.0" ixz="0.0" iyz="0.0" />
        </inertial>
    </link>
    <link name="wall">
        <visual>
            <origin rpy="0 0 0" xyz="0 0 0" />
            <geometry>
                <box size="2 0.01 2" />
            </geometry>
            <material name="white" />
        </visual>
        <collision>
            <origin rpy="0 0 0" xyz="0 0 0" />
            <geometry>
                <box size="2 0.01 2" />
            </geometry>
        </collision>
        <inertial>
            <mass value="0.1" />
            <origin xyz="0 0 0" rpy="0 0 0" />
            <inertia ixx="0.03" iyy="0.03" izz="0.03" ixy="0.0" ixz="0.0" iyz="0.0" />
        </inertial>
    </link>
    <joint name="table_to_wall" type="fixed">
        <parent link="table" />
        <child link="wall" />
        <origin xyz="0 -0.3925 0.9" />
    </joint>
    <joint name="mount_to_table" type="fixed">
        <parent link="mount" />
        <child link="table" />
        <origin xyz="0 -0.5925 0" />
    </joint>
    <!--The robot will be on the top surface of the box in the center-->
    <joint name="mount_to_robot" type="fixed">
        <parent link="mount" />
        <child link="base_link" />
        <origin rpy="0 0 0" xyz="0 0 0.9" />
    </joint>
    <transmission name="left_gear_joint_trans">
        <type>transmission_interface/SimpleTransmission</type>
        <joint name="left_gear_joint">
            <hardwareInterface>hardware_interface/PositionJointInterface</hardwareInterface>
        </joint>
        <actuator name="left_gear_joint_motor">
            <mechanicalReduction>1</mechanicalReduction>
            <hardwareInterface>hardware_interface/EffortJointInterface</hardwareInterface>
        </actuator>
    </transmission>
    <gazebo>
        <!-- loading plugin: mimic joints works in gazebo now-->
        <plugin filename="libroboticsgroup_gazebo_mimic_joint_plugin.so" name="mimic_joint">
            <joint>left_gear_joint</joint>
            <mimicJoint>right_gear_joint</mimicJoint>
            <multiplier>1.0</multiplier>
        </plugin>
        <plugin filename="libroboticsgroup_gazebo_mimic_joint_plugin.so" name="mimic_joint">
            <joint>left_gear_joint</joint>
            <mimicJoint>right_arm_bottom_joint</mimicJoint>
            <multiplier>-1.0</multiplier>
        </plugin>
        <plugin filename="libroboticsgroup_gazebo_mimic_joint_plugin.so" name="mimic_joint">
            <joint>left_gear_joint</joint>
            <mimicJoint>left_arm_bottom_joint</mimicJoint>
            <multiplier>1.0</multiplier>
        </plugin>
        <plugin filename="libroboticsgroup_gazebo_mimic_joint_plugin.so" name="mimic_joint">
            <joint>left_gear_joint</joint>
            <mimicJoint>right_arm_top_joint</mimicJoint>
            <multiplier>-1.0</multiplier>
        </plugin>
        <plugin filename="libroboticsgroup_gazebo_mimic_joint_plugin.so" name="mimic_joint">
            <joint>left_gear_joint</joint>
            <mimicJoint>left_arm_top_joint</mimicJoint>
            <multiplier>1.0</multiplier>
        </plugin>
        <plugin filename="libroboticsgroup_gazebo_mimic_joint_plugin.so" name="mimic_joint">
            <joint>left_gear_joint</joint>
            <mimicJoint>left_stick_joint</mimicJoint>
            <multiplier>-1.0</multiplier>
        </plugin>
        <plugin filename="libroboticsgroup_gazebo_mimic_joint_plugin.so" name="mimic_joint">
            <joint>left_gear_joint</joint>
            <mimicJoint>right_stick_joint</mimicJoint>
            <multiplier>1.0</multiplier>
        </plugin>
        <plugin filename="libroboticsgroup_gazebo_mimic_joint_plugin.so" name="mimic_joint">
            <joint>left_gear_joint</joint>
            <mimicJoint>left_stick_top_joint</mimicJoint>
            <multiplier>-1.0</multiplier>
        </plugin>
        <plugin filename="libroboticsgroup_gazebo_mimic_joint_plugin.so" name="mimic_joint">
            <joint>left_gear_joint</joint>
            <mimicJoint>right_stick_top_joint</mimicJoint>
            <multiplier>1.0</multiplier>
        </plugin>
        <plugin name="gazebo_ros_control">
            <robotNamespace>/</robotNamespace>
        </plugin>
    </gazebo>
    <!-- inertia factor -->
    <link name="base_bottom">
        <visual>
            <geometry>
                <mesh filename="package://ur3_sim_description/meshes/gripper/BaseBottom.dae" scale="0.001 0.001 0.001" />
            </geometry>
        </visual>
        <collision>
            <geometry>
                <mesh filename="package://ur3_sim_description/meshes/gripper/BaseBottom.dae" scale="0.001 0.001 0.001" />
            </geometry>
        </collision>
        <inertial>
            <mass value="0.00002265" />
            <origin rpy="0 0 0" xyz="0.022834885 -0.035958401 0.002623114" />
            <inertia ixx="0.00198528736" ixy="-0.00000264564125000" ixz="-0.00000829723937500" iyx="-0.00000264564125000" iyy="0.00093770280000000" iyz="0.00025834140000000" izx="-0.00000829723937500" izy="0.00025834140000000" izz="0.00252391792000000" />
        </inertial>
    </link>
    <gazebo reference="base_bottom">
        <material>Gazebo/DarkGrey</material>
        <turnGravityOff>true</turnGravityOff>
    </gazebo>
    <link name="adapter">
        <visual>
            <geometry>
                <mesh filename="package://ur3_sim_description/meshes/gripper/Adapter.dae" scale="0.001 0.001 0.001" />
            </geometry>
        </visual>
        <collision>
            <geometry>
                <mesh filename="package://ur3_sim_description/meshes/gripper/Adapter.dae" scale="0.001 0.001 0.001" />
            </geometry>
        </collision>
        <inertial>
            <mass value="0.00002265" />
            <origin rpy="0 0 0" xyz="0.022834885 -0.035958401 0.002623114" />
            <inertia ixx="0.00198528736" ixy="-0.00000264564125000" ixz="-0.00000829723937500" iyx="-0.00000264564125000" iyy="0.00093770280000000" iyz="0.00025834140000000" izx="-0.00000829723937500" izy="0.00025834140000000" izz="0.00252391792000000" />
        </inertial>
    </link>
    <gazebo reference="adapter">
        <material>Gazebo/DarkGrey</material>
        <turnGravityOff>true</turnGravityOff>
    </gazebo>
    <joint name="adapter_joint" type="fixed">
        <parent link="base_bottom" />
        <child link="adapter" />
        <origin xyz="0.0 0 0.0" />
    </joint>
    <link name="left_gear">
        <visual>
            <origin xyz="0.0 0 0.0" />
            <geometry>
                <mesh filename="package://ur3_sim_description/meshes/gripper/MainGear2.dae" scale="0.001 0.001 0.001" />
            </geometry>
        </visual>
        <collision>
            <origin xyz="0.0 0 0.0" />
            <geometry>
                <mesh filename="package://ur3_sim_description/meshes/gripper/MainGear2.dae" scale="0.001 0.001 0.001" />
            </geometry>
        </collision>
        <inertial>
            <mass value="0.00002265" />
            <origin rpy="0 0 0" xyz="-0.004189223000000001 -6.5e-08 0.009676432" />
            <!--  divide by 10E-11     -->
            <inertia ixx="4.8774819999999994e-05" ixy="-3.4191254e-10" ixz="-4.165070312499999e-06" iyx="-3.4191254e-10" iyy="9.591456999999999e-05" iyz="5.05108643e-09" izx="-4.165070312499999e-06" izy="5.05108643e-09" izz="5.05108643e-09" />
        </inertial>
    </link>
    <gazebo reference="left_gear">
        <material>Gazebo/Grey</material>
        <turnGravityOff>true</turnGravityOff>
    </gazebo>
    <joint name="left_gear_joint" type="revolute">
        <parent link="base_bottom" />
        <child link="left_gear" />
        <axis xyz="0 0 -1" />
        <origin xyz="0.0 0 0.0" />
        <limit effort="1000.0" lower="-2.0" upper="2.0" velocity="0.5" />
    </joint>
    <link name="right_gear">
        <visual>
            <origin xyz="-0.044341 0 0.0" />
            <geometry>
                <mesh filename="package://ur3_sim_description/meshes/gripper/MainGear1.dae" scale="0.001 0.001 0.001" />
            </geometry>
        </visual>
        <collision>
            <origin xyz="-0.044341 0 0.0" />
            <geometry>
                <mesh filename="package://ur3_sim_description/meshes/gripper/MainGear1.dae" scale="0.001 0.001 0.001" />
            </geometry>
        </collision>
        <inertial>
            <mass value="0.00002265" />
            <origin rpy="0 0 0" xyz="0.048526249 -1.46e-07 0.009676307" />
            <!--  divide by 10E-11     -->
            <inertia ixx="4.8844599999999996e-05" ixy="8.5138191e-10" ixz="4.1636959375e-06" iyx="8.5138191e-10" iyy="9.598415999999999e-05" iyz="-5.2216833499999995e-09" izx="4.1636959375e-06" izy="4.1636959375e-06" izz="0.00012235934999999998" />
        </inertial>
    </link>
    <gazebo reference="right_gear">
        <material>Gazebo/Grey</material>
        <turnGravityOff>true</turnGravityOff>
    </gazebo>
    <joint name="right_gear_joint" type="revolute">
        <parent link="base_bottom" />
        <child link="right_gear" />
        <axis xyz="0 0 1" />
        <origin xyz="0.044341 0 0.0" />
        <limit effort="1000.0" lower="-2.0" upper="2.0" velocity="0.5" />
        <mimic joint="left_gear_joint" multiplier="1" offset="0" />
    </joint>
    <link name="right_arm_bottom">
        <visual>
            <origin xyz="-0.094414 0 0.0" />
            <geometry>
                <mesh filename="package://ur3_sim_description/meshes/gripper/Arm_R_Bottom.dae" scale="0.001 0.001 0.001" />
            </geometry>
        </visual>
        <collision>
            <origin xyz="-0.094414 0 0.0" />
            <geometry>
                <mesh filename="package://ur3_sim_description/meshes/gripper/Arm_R_Bottom.dae" scale="0.001 0.001 0.001" />
            </geometry>
        </collision>
        <inertial>
            <mass value="0.0001" />
            <inertia ixx="0.001" ixy="0.0" ixz="0.0" iyy="0.001" iyz="0.0" izz="0.001" />
            <origin xyz="0 0 0" rpy="0 0 0" />
        </inertial>
    </link>
    <gazebo reference="right_arm_bottom">
        <material>Gazebo/DarkGrey</material>
        <turnGravityOff>true</turnGravityOff>
    </gazebo>
    <joint name="right_arm_bottom_joint" type="revolute">
        <joint_properties damping="1000.0" friction="1000.0" />
        <parent link="right_gear" />
        <child link="right_arm_bottom" />
        <axis xyz="0 0 1" />
        <origin xyz="0.050137 0 0.0" />
        <limit effort="1000.0" lower="-2.0" upper="2.0" velocity="0.5" />
        <mimic joint="left_gear_joint" multiplier="-1" offset="0" />
    </joint>
    <link name="left_arm_bottom">
        <visual>
            <origin xyz="0.050137 0 0.0" />
            <geometry>
                <mesh filename="package://ur3_sim_description/meshes/gripper/Arm_L_Bottom.dae" scale="0.001 0.001 0.001" />
            </geometry>
        </visual>
        <collision>
            <origin xyz="0.050137 0 0.0" />
            <geometry>
                <mesh filename="package://ur3_sim_description/meshes/gripper/Arm_L_Bottom.dae" scale="0.001 0.001 0.001" />
            </geometry>
        </collision>
        <inertial>
            <mass value="0.0001" />
            <inertia ixx="0.001" ixy="0.0" ixz="0.0" iyy="0.001" iyz="0.0" izz="0.001" />
            <origin xyz="0 0 0" rpy="0 0 0" />
        </inertial>
    </link>
    <gazebo reference="left_arm_bottom">
        <material>Gazebo/DarkGrey</material>
        <turnGravityOff>true</turnGravityOff>
    </gazebo>
    <joint name="left_arm_bottom_joint" type="revolute">
        <joint_properties damping="1000.0" friction="1000.0" />
        <parent link="left_gear" />
        <child link="left_arm_bottom" />
        <axis xyz="0 0 1" />
        <origin xyz="-0.050137 0 0.0" />
        <limit effort="1000.0" lower="-2.0" upper="2.0" velocity="0.5" />
        <mimic joint="left_gear_joint" multiplier="1" offset="0" />
    </joint>
    <link name="right_arm_top">
        <visual>
            <origin rpy="0.0 0.0 0.0" xyz="0.060137 0 0.027123" />
            <geometry>
                <mesh filename="package://ur3_sim_description/meshes/gripper/Arm_R_Top.dae" scale="0.001 0.001 0.001" />
            </geometry>
        </visual>
        <collision>
            <origin rpy="0.0 0.0 0.0" xyz="0.060137  0 0.027123" />
            <geometry>
                <mesh filename="package://ur3_sim_description/meshes/gripper/Arm_R_Top.dae" scale="0.001 0.001 0.001" />
            </geometry>
        </collision>
        <inertial>
            <mass value="0.0001" />
            <inertia ixx="0.001" ixy="0.0" ixz="0.0" iyy="0.001" iyz="0.0" izz="0.001" />
            <origin xyz="0 0 0" rpy="0 0 0" />
        </inertial>
    </link>
    <gazebo reference="right_arm_top">
        <material>Gazebo/DarkGrey</material>
        <turnGravityOff>true</turnGravityOff>
    </gazebo>
    <joint name="right_arm_top_joint" type="revolute">
        <parent link="right_gear" />
        <child link="right_arm_top" />
        <axis xyz="0 0 1" />
        <origin xyz="0.050137  0 0.0" />
        <limit effort="1000.0" lower="-2.0" upper="2.0" velocity="0.5" />
        <mimic joint="left_gear_joint" multiplier="-1" offset="0" />
    </joint>
    <link name="left_arm_top">
        <visual>
            <origin xyz="0.050137 0 0.0" />
            <geometry>
                <mesh filename="package://ur3_sim_description/meshes/gripper/Arm_L_Top.dae" scale="0.001 0.001 0.001" />
            </geometry>
        </visual>
        <collision>
            <origin xyz="0.050137 0 0.0" />
            <geometry>
                <mesh filename="package://ur3_sim_description/meshes/gripper/Arm_L_Top.dae" scale="0.001 0.001 0.001" />
            </geometry>
        </collision>
        <inertial>
            <mass value="0.0001" />
            <inertia ixx="0.001" ixy="0.0" ixz="0.0" iyy="0.001" iyz="0.0" izz="0.001" />
            <origin xyz="0 0 0" rpy="0 0 0" />
        </inertial>
    </link>
    <gazebo reference="left_arm_top">
        <material>Gazebo/DarkGrey</material>
        <turnGravityOff>true</turnGravityOff>
    </gazebo>
    <joint name="left_arm_top_joint" type="revolute">
        <parent link="left_gear" />
        <child link="left_arm_top" />
        <axis xyz="0 0 1" />
        <origin xyz="-0.050137 0 0.0" />
        <limit effort="1000.0" lower="-2.0" upper="2.0" velocity="0.5" />
        <mimic joint="left_gear_joint" multiplier="1" offset="0" />
    </joint>
    <link name="left_finger">
        <visual>
            <geometry>
                <mesh filename="package://ur3_sim_description/meshes/gripper/Sock1.dae" scale="0.001 0.001 0.001" />
            </geometry>
        </visual>
        <collision>
            <geometry>
                <mesh filename="package://ur3_sim_description/meshes/gripper/Sock1.dae" scale="0.001 0.001 0.001" />
            </geometry>
        </collision>
        <inertial>
            <mass value="0.0000002265" />
            <origin rpy="0 0 0" xyz="-0.025071934 0.06901268 0.008750031" />
            <!--  divide by 10E-11     -->
            <inertia ixx="5.3334145e-05" ixy="2.1136374999999998e-07" ixz="3.0323486e-10" iyx="2.1136374999999998e-07" iyy="4.08043475e-05" iyz="3.2196716e-10" izx="3.0323486e-10" izy="3.2196716e-10" izz="2.61154725e-05" />
        </inertial>
    </link>
    <gazebo reference="left_finger">
        <material>Gazebo/DarkYellow</material>
        <gravity>0</gravity>
        <turnGravityOff>true</turnGravityOff>
    </gazebo>
    <joint name="left_finger_joint" type="fixed">
        <parent link="left_arm_bottom" />
        <child link="left_finger" />
        <origin xyz="0.050137  0 0.0" />
    </joint>
    <link name="right_finger">
        <visual>
            <geometry>
                <mesh filename="package://ur3_sim_description/meshes/gripper/Sock2.dae" scale="0.001 0.001 0.001" />
            </geometry>
        </visual>
        <collision>
            <geometry>
                <mesh filename="package://ur3_sim_description/meshes/gripper/Sock2.dae" scale="0.001 0.001 0.001" />
            </geometry>
        </collision>
        <inertial>
            <mass value="0.0000002265" />
            <!--  divide by 10E-11     -->
            <inertia ixx="5.3334145e-05" ixy="2.1136374999999998e-07" ixz="3.0323486e-10" iyx="2.1136374999999998e-07" iyy="4.08043475e-05" iyz="3.2196716e-10" izx="3.0323486e-10" izy="3.2196716e-10" izz="2.61154725e-05" />
            <origin xyz="0 0 0" rpy="0 0 0" />
        </inertial>
    </link>
    <gazebo reference="right_finger">
        <material>Gazebo/DarkYellow</material>
        <turnGravityOff>true</turnGravityOff>
    </gazebo>
    <joint name="right_finger_joint" type="fixed">
        <parent link="right_arm_bottom" />
        <child link="right_finger" />
        <origin xyz="-0.094414  0 0" />
    </joint>
    <link name="left_stick">
        <visual>
            <origin xyz="-0.01 -0.033 0.0" />
            <geometry>
                <mesh filename="package://ur3_sim_description/meshes/gripper/Stick1.dae" scale="0.001 0.001 0.001" />
            </geometry>
        </visual>
        <collision>
            <origin xyz="-0.01 -0.033 0.0" />
            <geometry>
                <mesh filename="package://ur3_sim_description/meshes/gripper/Stick1.dae" scale="0.001 0.001 0.001" />
            </geometry>
        </collision>
        <inertial>
            <mass value="0.00002265" />
            <origin rpy="0 0 0" xyz="-0.005003726 0.0 0.005024187" />
            <!--  divide by 10E-11     -->
            <inertia ixx="9.2893898438e-07" ixy="4.8491e-13" ixz="1.07669724e-09" iyx="4.8491e-13" iyy="1.508868875e-05" iyz="-2.6804e-13" izx="1.07669724e-09" izy="-2.6804e-13" izz="1.5085463749999999e-05" />
        </inertial>
    </link>
    <gazebo reference="left_stick">
        <material>Gazebo/Grey</material>
        <turnGravityOff>true</turnGravityOff>
    </gazebo>
    <joint name="left_stick_joint" type="revolute">
        <parent link="base_bottom" />
        <child link="left_stick" />
        <axis xyz="0 0 1" />
        <origin xyz="0.01 0.033 0.0" />
        <limit effort="1000.0" lower="-2.0" upper="2.0" velocity="0.5" />
        <mimic joint="left_gear_joint" multiplier="-1" offset="0" />
    </joint>
    <link name="right_stick">
        <visual>
            <origin xyz="-0.034341 -0.033 0.0" />
            <geometry>
                <mesh filename="package://ur3_sim_description/meshes/gripper/Stick2.dae" scale="0.001 0.001 0.001" />
            </geometry>
        </visual>
        <collision>
            <origin xyz="-0.034341 -0.033 0.0" />
            <geometry>
                <mesh filename="package://ur3_sim_description/meshes/gripper/Stick2.dae" scale="0.001 0.001 0.001" />
            </geometry>
        </collision>
        <inertial>
            <mass value="0.00002265" />
            <origin rpy="0 0 0" xyz="0.059337273 0.033 0.005024188" />
            <!--  divide by 10E-11     -->
            <inertia ixx="9.289412499999999e-07" ixy="7.831899999999999e-13" ixz="1.07686089e-09" iyx="7.831899999999999e-13" iyy="1.508869375e-05" iyz="6.557200000000001e-13" izx="1.07686089e-09" izy="6.557200000000001e-13" izz="1.508545e-05" />
        </inertial>
    </link>
    <gazebo reference="right_stick">
        <material>Gazebo/Grey</material>
        <turnGravityOff>true</turnGravityOff>
    </gazebo>
    <joint name="right_stick_joint" type="revolute">
        <parent link="base_bottom" />
        <child link="right_stick" />
        <axis xyz="0 0 1" />
        <origin xyz="0.034341 0.033 0.0" />
        <limit effort="1000.0" lower="-2.0" upper="2.0" velocity="0.5" />
        <mimic joint="left_gear_joint" multiplier="1" offset="0" />
    </joint>
    <link name="spacer">
        <visual>
            <geometry>
                <mesh filename="package://ur3_sim_description/meshes/gripper/Spacer.dae" scale="0.001 0.001 0.001" />
            </geometry>
        </visual>
        <collision>
            <geometry>
                <mesh filename="package://ur3_sim_description/meshes/gripper/Spacer.dae" scale="0.001 0.001 0.001" />
            </geometry>
        </collision>
        <inertial>
            <mass value="0.00002265" />
            <origin rpy="0 0 0" xyz="0.022172432000000002 0.031563816 0.015463399000000001" />
            <!--  divide by 10E-11     -->
            <inertia ixx="1.8169903124999999e-06" ixy="-1.4737192e-10" ixz="-5.3030239e-10" iyx="-1.4737192e-10" iyy="5.471119375e-06" iyz="5.471119375e-06" izx="5.471119375e-06" izy="5.471119375e-06" izz="6.42384e-06" />
        </inertial>
    </link>
    <gazebo reference="spacer">
        <material>Gazebo/DarkGrey</material>
        <turnGravityOff>true</turnGravityOff>
    </gazebo>
    <joint name="spacer_joint" type="fixed">
        <parent link="base_bottom" />
        <child link="spacer" />
        <!--    <origin xyz="-0.094414  0 0.0"/>-->
    </joint>
    <link name="left_stick_top">
        <visual>
            <origin xyz="-0.01 -0.033 0.0" />
            <geometry>
                <mesh filename="package://ur3_sim_description/meshes/gripper/Stick_Top1.dae" scale="0.001 0.001 0.001" />
            </geometry>
        </visual>
        <collision>
            <origin xyz="-0.01 -0.033 0.0" />
            <geometry>
                <mesh filename="package://ur3_sim_description/meshes/gripper/Stick_Top1.dae" scale="0.001 0.001 0.001" />
            </geometry>
        </collision>
        <inertial>
            <mass value="0.00002265" />
            <origin rpy="0 0 0" xyz="-0.005003726 0.0 0.005024187" />
            <!--  divide by 10E-11     -->
            <inertia ixx="9.2893898438e-07" ixy="4.8491e-13" ixz="1.07669724e-09" iyx="4.8491e-13" iyy="1.508868875e-05" iyz="-2.6804e-13" izx="1.07669724e-09" izy="-2.6804e-13" izz="1.5085463749999999e-05" />
        </inertial>
    </link>
    <gazebo reference="left_stick_top">
        <material>Gazebo/Grey</material>
        <turnGravityOff>true</turnGravityOff>
    </gazebo>
    <joint name="left_stick_top_joint" type="revolute">
        <parent link="base_bottom" />
        <child link="left_stick_top" />
        <axis xyz="0 0 1" />
        <origin xyz="0.01 0.033 0.0" />
        <limit effort="1000.0" lower="-2.0" upper="2.0" velocity="0.5" />
        <mimic joint="left_gear_joint" multiplier="-1" offset="0" />
    </joint>
    <link name="right_stick_top">
        <visual>
            <origin xyz="-0.034341 -0.033 0.0" />
            <geometry>
                <mesh filename="package://ur3_sim_description/meshes/gripper/Stick_Top2.dae" scale="0.001 0.001 0.001" />
            </geometry>
        </visual>
        <collision>
            <origin xyz="-0.034341 -0.033 0.0" />
            <geometry>
                <mesh filename="package://ur3_sim_description/meshes/gripper/Stick_Top2.dae" scale="0.001 0.001 0.001" />
            </geometry>
        </collision>
        <inertial>
            <mass value="0.00002265" />
            <origin rpy="0 0 0" xyz="0.059337273 0.033 0.005024188" />
            <!--  divide by 10E-11     -->
            <inertia ixx="9.289412499999999e-07" ixy="7.831899999999999e-13" ixz="1.07686089e-09" iyx="7.831899999999999e-13" iyy="1.508869375e-05" iyz="6.557200000000001e-13" izx="1.07686089e-09" izy="6.557200000000001e-13" izz="1.508545e-05" />
        </inertial>
    </link>
    <gazebo reference="right_stick_top">
        <material>Gazebo/Grey</material>
        <turnGravityOff>true</turnGravityOff>
    </gazebo>
    <joint name="right_stick_top_joint" type="revolute">
        <parent link="base_bottom" />
        <child link="right_stick_top" />
        <axis xyz="0 0 1" />
        <origin xyz="0.034341 0.033 0.0" />
        <limit effort="1000.0" lower="-2.0" upper="2.0" velocity="0.5" />
        <mimic joint="left_gear_joint" multiplier="1" offset="0" />
    </joint>
    <link name="base_top">
        <visual>
            <geometry>
                <mesh filename="package://ur3_sim_description/meshes/gripper/BaseTopCamera.dae" scale="0.001 0.001 0.001" />
            </geometry>
        </visual>
        <collision>
            <geometry>
                <mesh filename="package://ur3_sim_description/meshes/gripper/BaseTopCamera.dae" scale="0.001 0.001 0.001" />
            </geometry>
        </collision>
        <inertial>
            <mass value="0.00002265" />
            <inertia ixx="0.00198528736" ixy="-0.00000264564125000" ixz="-0.00000829723937500" iyx="-0.00000264564125000" iyy="0.00093770280000000" iyz="0.00025834140000000" izx="-0.00000829723937500" izy="0.00025834140000000" izz="0.00252391792000000" />
            <origin xyz="0 0 0" rpy="0 0 0" />
        </inertial>
    </link>
    <gazebo reference="base_top">
        <material>Gazebo/DarkGrey</material>
        <turnGravityOff>true</turnGravityOff>
    </gazebo>
    <joint name="base_top_joint" type="fixed">
        <parent link="base_bottom" />
        <child link="base_top" />
        <origin rpy="0.0 0.0 3.141592653589793" xyz="0.0 0.0 0.0205" />
    </joint>
    <!--<joint name="gripper" type="fixed">
      <origin xyz="0.00875 0.022171 0.0814375" rpy="${3.141/2.0} 0.0 ${-3.141/2.0}" />
      <parent link="tool0" />
      <child link="base_bottom" />
    </joint>-->
    <link name="cable_block">
        <visual>
            <geometry>
                <mesh filename="package://ur3_sim_description/meshes/gripper/CableBlock.dae" scale="0.001 0.001 0.001" />
            </geometry>
        </visual>
        <collision>
            <geometry>
                <mesh filename="package://ur3_sim_description/meshes/gripper/CableBlock.dae" scale="0.001 0.001 0.001" />
            </geometry>
        </collision>
        <inertial>
            <mass value="0.1" />
            <origin xyz="0 0 0" rpy="0 0 0" />
            <inertia ixx="0.03" iyy="0.03" izz="0.03" ixy="0.0" ixz="0.0" iyz="0.0" />
        </inertial>
    </link>
    <joint name="cable_block_joint" type="fixed">
        <origin rpy="0.0 0.0 3.141" xyz="0.0 0.0 0.0" />
        <parent link="base_bottom" />
        <child link="cable_block" />
    </joint>
    <link name="tool_gripper" />
    <joint name="tool_gripper_joint" type="fixed">
        <parent link="robotiq_ft_frame_id" />
        <child link="tool_gripper" />
        <origin rpy="0.0 0.0 0.0" xyz="-0.02 0.01 0.085" />
    </joint>
    <joint name="prova" type="fixed">
        <parent link="tool_gripper" />
        <child link="base_bottom" />
        <origin rpy="1.57079632679 0.0 0.0" xyz="0.0 0.0 0.0" />
    </joint>
    <transmission name="trans_right_gear_joint">
        <type>transmission_interface/SimpleTransmission</type>
        <joint name="right_gear_joint">
            <hardwareInterface>hardware_interface/EffortJointInterface</hardwareInterface>
        </joint>
        <actuator name="right_gear_joint_motor">
            <hardwareInterface>hardware_interface/EffortJointInterface</hardwareInterface>
            <mechanicalReduction>1</mechanicalReduction>
        </actuator>
    </transmission>
    <transmission name="trans_right_arm_bottom_joint">
        <type>transmission_interface/SimpleTransmission</type>
        <joint name="right_arm_bottom_joint">
            <hardwareInterface>hardware_interface/EffortJointInterface</hardwareInterface>
        </joint>
        <actuator name="right_arm_bottom_joint_motor">
            <hardwareInterface>hardware_interface/EffortJointInterface</hardwareInterface>
            <mechanicalReduction>1</mechanicalReduction>
        </actuator>
    </transmission>
    <transmission name="trans_left_arm_bottom_joint">
        <type>transmission_interface/SimpleTransmission</type>
        <joint name="left_arm_bottom_joint">
            <hardwareInterface>hardware_interface/EffortJointInterface</hardwareInterface>
        </joint>
        <actuator name="left_arm_bottom_joint_motor">
            <hardwareInterface>hardware_interface/EffortJointInterface</hardwareInterface>
            <mechanicalReduction>1</mechanicalReduction>
        </actuator>
    </transmission>
    <transmission name="trans_right_arm_top_joint">
        <type>transmission_interface/SimpleTransmission</type>
        <joint name="right_arm_top_joint">
            <hardwareInterface>hardware_interface/EffortJointInterface</hardwareInterface>
        </joint>
        <actuator name="right_arm_top_joint_motor">
            <hardwareInterface>hardware_interface/EffortJointInterface</hardwareInterface>
            <mechanicalReduction>1</mechanicalReduction>
        </actuator>
    </transmission>
    <transmission name="trans_left_arm_top_joint">
        <type>transmission_interface/SimpleTransmission</type>
        <joint name="left_arm_top_joint">
            <hardwareInterface>hardware_interface/EffortJointInterface</hardwareInterface>
        </joint>
        <actuator name="left_arm_top_joint_motor">
            <hardwareInterface>hardware_interface/EffortJointInterface</hardwareInterface>
            <mechanicalReduction>1</mechanicalReduction>
        </actuator>
    </transmission>
    <transmission name="trans_left_stick_joint">
        <type>transmission_interface/SimpleTransmission</type>
        <joint name="left_stick_joint">
            <hardwareInterface>hardware_interface/EffortJointInterface</hardwareInterface>
        </joint>
        <actuator name="left_stick_joint_motor">
            <hardwareInterface>hardware_interface/EffortJointInterface</hardwareInterface>
            <mechanicalReduction>1</mechanicalReduction>
        </actuator>
    </transmission>
    <transmission name="trans_right_stick_joint">
        <type>transmission_interface/SimpleTransmission</type>
        <joint name="right_stick_joint">
            <hardwareInterface>hardware_interface/EffortJointInterface</hardwareInterface>
        </joint>
        <actuator name="right_stick_joint_motor">
            <hardwareInterface>hardware_interface/EffortJointInterface</hardwareInterface>
            <mechanicalReduction>1</mechanicalReduction>
        </actuator>
    </transmission>
    <transmission name="trans_left_stick_top_joint">
        <type>transmission_interface/SimpleTransmission</type>
        <joint name="left_stick_top_joint">
            <hardwareInterface>hardware_interface/EffortJointInterface</hardwareInterface>
        </joint>
        <actuator name="left_stick_top_joint_motor">
            <hardwareInterface>hardware_interface/EffortJointInterface</hardwareInterface>
            <mechanicalReduction>1</mechanicalReduction>
        </actuator>
    </transmission>
    <transmission name="trans_right_stick_top_joint">
        <type>transmission_interface/SimpleTransmission</type>
        <joint name="right_stick_top_joint">
            <hardwareInterface>hardware_interface/EffortJointInterface</hardwareInterface>
        </joint>
        <actuator name="right_stick_top_joint_motor">
            <hardwareInterface>hardware_interface/EffortJointInterface</hardwareInterface>
            <mechanicalReduction>1</mechanicalReduction>
        </actuator>
    </transmission>
</robot>

